Workbook

Sheet Acerno_Cache_XXXXX

Sheet Resumen
A1: FIRMA | B1: REGIONAL | C1: NÚMERO PROCESOS AUDITADOS | D1: 10% DE PROCESOS AUDITADOS | E1: NÚMER PROCESOS CON ERROR | F1: PORCENTAJE PROCESOS CON ERROR | G1: CONCLUSIÓN
A2: JURISCOL ABOGADOS SAS | B2: BOGOTA | C2: =COUNTIF(BASE!A:A,A2) -> 87 | D2: =ROUNDUP(C2*0.1,0) -> 9 | E2: =COUNTIFS(BASE!AU:AU,"GENERA DESCUENTO",BASE!A:A,A2) -> 0 | F2: =IFERROR(E2/C2,0) -> 0 | G2: =IF(F2>=10%,"APLICAR DESCUENTO","NO APLICAR DESCUENTO") -> NO APLICAR DESCUENTO
A3: TABOR ASESORES LEGALES SAS | B3: BOGOTA | C3: =COUNTIF(BASE!A:A,A3) -> 183 | D3: =ROUNDUP(C3*0.1,0) -> 19 | E3: =COUNTIFS(BASE!AU:AU,"GENERA DESCUENTO",BASE!A:A,A3) -> 0 | F3: =IFERROR(E3/C3,0) -> 0 | G3: =IF(F3>=10%,"APLICAR DESCUENTO","NO APLICAR DESCUENTO") -> NO APLICAR DESCUENTO
A4: TRUJILLO POLANIA Y ASOCIADOS | B4: BOGOTA | C4: =COUNTIF(BASE!A:A,A4) -> 79 | D4: =ROUNDUP(C4*0.1,0) -> 8 | E4: =COUNTIFS(BASE!AU:AU,"GENERA DESCUENTO",BASE!A:A,A4) -> 0 | F4: =IFERROR(E4/C4,0) -> 0 | G4: =IF(F4>=10%,"APLICAR DESCUENTO","NO APLICAR DESCUENTO") -> NO APLICAR DESCUENTO
A5: VENCE SALAMANCA LAWYERS GROUP SAS | B5: BOGOTA | C5: =COUNTIF(BASE!A:A,A5) -> 139 | D5: =ROUNDUP(C5*0.1,0) -> 14 | E5: =COUNTIFS(BASE!AU:AU,"GENERA DESCUENTO",BASE!A:A,A5) -> 0 | F5: =IFERROR(E5/C5,0) -> 0 | G5: =IF(F5>=10%,"APLICAR DESCUENTO","NO APLICAR DESCUENTO") -> NO APLICAR DESCUENTO
A6: WORLD LEGAL CORPORATION SAS | B6: BOGOTA | C6: =COUNTIF(BASE!A:A,A6) -> 104 | D6: =ROUNDUP(C6*0.1,0) -> 11 | E6: =COUNTIFS(BASE!AU:AU,"GENERA DESCUENTO",BASE!A:A,A6) -> 0 | F6: =IFERROR(E6/C6,0) -> 0 | G6: =IF(F6>=10%,"APLICAR DESCUENTO","NO APLICAR DESCUENTO") -> NO APLICAR DESCUENTO

Sheet CON REPLICA
A1: FIRMA | B1: ID_PROCESOS | C1: NO_BIZAGI | D1: ID_EKOGUI | E1: DIGITOS_23 | F1: 21 DIG | G1: TIPO_PROCESO | H1: IDENTIFICACION_DEMANDANTE | I1: NOMBRE_DEMANDANTE | J1: DEMANDADO | K1: REGIONAL | L1: SENTIDO_FALLO_1INSTANCIA | M1: FECHA_FALLO_1INSTANCIA | N1: SENTIDO_FALLO_2INSTANCIA | O1: FECHA_FALLO_2INSTANCIA | P1: DEMANDA | Q1: OBSERVACIÓN DEMANDA | R1: ACTA_DE_AUDIENCIA | S1: OBSERVACIÓN ACTA_DE_AUDIENCIA | T1: CONTESTACION_DE_DEMANDA | U1: OBSERVACIÓN CONTESTACION_DE_DEMANDA | V1: SENTENCIA_PRIMERA_INSTANCIA | W1: OBSERVACIÓN SENTENCIA_PRIMERA_INSTANCIA | X1: SENTENCIA_SEGUNDA_INSTANCIA | Y1: OBSERVACIÓN SENTENCIA_SEGUNDA_INSTANCIA | Z1: DEMANDA | AA1: OBSERVACIÓN DEMANDA | AB1: MANDAMIENTO_DE_PAGO | AC1: OBSERVACIÓN MANDAMIENTO_DE_PAGO | AD1: EXCEPCIONES_CONTESTACION | AE1: OBSERVACIÓN EXCEPCIONES_CONTESTACION | AF1: AUTO_QUE_ORDENA_CONTINUAR/NO_CONTINUAR_CON _LA_EJECUCION | AG1: OBSERVACIÓN AUTO_QUE_ORDENA_CONTINUAR/NO_CONTINUAR_CON _LA_EJECUCION | AH1: VALIDACIÓN | AI1: OBSERVACIÓN ERROR | AJ1: PROCEDE / NO PROCEDE ERROR | AK1: RAZÓN POR LA CUAL NO PROCEDE | AL1: OBSERVACIÓN REGIONAL | AM1: CONCLUSIÓN | AN1: ENCARGADO | AO1: Responsables | AR1: REVISOR REGIONAL
A2: TABOR ASESORES LEGALES SAS | B2: ID_007159842 | C2: 2022_2383761 | D2: 2270960 | E2: 11001310501920210043700 | G2: ORDINARIO LABORAL DE PRIMERA INSTANCIA | H2: 19498167 | I2: JUAN CARLOS CASTELLANOS CRUZ | J2: Colpensiones | K2: BOGOTA | L2: DESFAVORABLE | M2: 25/06/2024 | N2: SIN FALLO | P2: SI | R2: SI | T2: SI | V2: SI | X2: NO | Y2: No se cargó en la plataforma ekogui la pieza procesal SENTENCIA. | AH2: ERROR | AI2: ////////No se cargó en la plataforma ekogui la pieza procesal SENTENCIA.//////// | AJ2: NO PROCEDE ERROR | AK2: EL DOCUMENTO SE ENCUENTRA CARGADO EN EKOGUI DESDE 2024/07/20 | AN2: ANA MARIA ROJAS | AQ2: X | AR2: ANA MARIA ROJAS
A3: WORLD LEGAL CORPORATION SAS | B3: ID_00611087 | C3: 2020_1463093 | D3: 1378379 | E3: 11001310500220180067700 | G3: ORDINARIO LABORAL DE PRIMERA INSTANCIA | H3: 212893 | I3: CARLOS HERNAN GONZALEZ POSADA | J3: Colpensiones | K3: BOGOTA | L3: FAVORABLE | M3: 5/09/2023 | N3: SIN FALLO | P3: NO | Q3: No se cargó en la plataforma ekogui la pieza procesal DEMANDA-ORDINARIA. | R3: SI | T3: SI | V3: SI | X3: NO | Y3: No se cargó en la plataforma ekogui la pieza procesal SENTENCIA. | AH3: ERROR | AI3: No se cargó en la plataforma ekogui la pieza procesal DEMANDA-ORDINARIA.////////No se cargó en la plataforma ekogui la pieza procesal SENTENCIA.//////// | AJ3: NO PROCEDE ERROR | AK3: LA SENTENCIA ESTA CARGADA DESDE 2024/07/23 -SENTENCIA- 11001310500220180067700.pdf | AN3: ANA MARIA ROJAS | AQ3: X | AR3: ANA MARIA ROJAS
A4: WORLD LEGAL CORPORATION SAS | B4: ID_007822556 | C4: 2025_5771852 | D4: 2633368 | E4: 11001310503520240032700 | G4: ORDINARIO LABORAL DE PRIMERA INSTANCIA | H4: 17135915 | I4: ANTONIO MARIA GOMEZ GARAY | J4: Colpensiones | K4: BOGOTA | L4: SIN FALLO | N4: SIN FALLO | P4: NO | Q4: No se cargó en la plataforma ekogui la pieza procesal DEMANDA-ORDINARIA. | T4: SI | AH4: ERROR | AI4: No se cargó en la plataforma ekogui la pieza procesal DEMANDA-ORDINARIA.//////////////// | AJ4: NO PROCEDE ERROR | AK4: LA PIEZA PROCESAL FUE CARGADA EN EKOGUI ANTES DE CORTE EL DIA: 2026/04/03 -NOTIFICACION AUTO ADMISORIO/MANDAMIENTO DE PAGO- DEMANDA.pdf | AN4: ANA MARIA ROJAS | AQ4: X | AR4: ANA MARIA ROJAS
A5: TRUJILLO POLANIA Y ASOCIADOS | B5: ID_00001239 | C5: SIN_BZ_1266 | D5: 1192223 | E5: 11001310500920120010300 | G5: EJECUTIVO LABORAL | H5: 17665468 | I5: JESUS MARIO LUJAN ARENAS | J5: COLPENSIONES | K5: BOGOTA | L5: CONTINUA CON LA EJECUCION | M5: 15/03/2013 | N5: SIN FALLO | Z5: NO | AA5: Se cargó en la plataforma ekogui la pieza procesal DEMANDA QUE DA ORIGEN AL MANDAMIENTO DE PAGO, pero es un comodín, pantallazo, o es otra pieza procesal. | AB5: NO | AC5: No se cargó en la plataforma ekogui la pieza procesal DEMANDA QUE DA ORIGEN AL MANDAMIENTO DE PAGO. | AH5: ERROR | AI5: //////////Se cargó en la plataforma ekogui la pieza procesal DEMANDA QUE DA ORIGEN AL MANDAMIENTO DE PAGO, pero es un comodín, pantallazo, o es otra pieza procesal.//No se cargó en la plataforma ekogui la pieza procesal DEMANDA QUE DA ORIGEN AL MANDAMIENTO DE PAGO.//// | AJ5: NO PROCEDE ERROR | AK5: EL CARGUE DE LA PIEZA MENCIONADA, NO SE DIO EN VIGENCIA DE LA FIRMA TRUJILLO POLANIA, SIN EMBARGO SE SOLICITA ACCESO AL EXPEDIENTE PARA DAR CORRECCION A LO SOLICITADO. (SE CARGAN TODAS LAS PIEZAS REQUERIDAS) | AN5: ANA MARIA ROJAS | AQ5: X | AR5: ANA MARIA ROJAS
A6: WORLD LEGAL CORPORATION SAS | B6: ID_007039569 | C6: 2021_8136033 | D6: 2217857 | E6: 11001310503520210019100 | G6: ORDINARIO LABORAL DE PRIMERA INSTANCIA | H6: 39781379 | I6: JACQUELINE MARGARET DANIEL SILVA | J6: Colpensiones | K6: BOGOTA | L6: DESFAVORABLE | M6: 7/07/2023 | N6: DESFAVORABLE | O6: 31/05/2024 | P6: SI | R6: SI | T6: SI | V6: NO | W6: Se cargó en la plataforma ekogui la pieza procesal SENTENCIA, pero es un comodín, pantallazo, o es otra pieza procesal. | AH6: ERROR | AI6: //////Se cargó en la plataforma ekogui la pieza procesal SENTENCIA, pero es un comodín, pantallazo, o es otra pieza procesal.////////// | AJ6: NO PROCEDE ERROR | AK6: EL ACTA REQUERIDA ES DE FECHA 07/07/2023, FECHA PARA LA CUAL LA FIRMA NO EJERCIA DEFENSA PARA LA ENTIDAD, POR LO TANTO GENERA COMPROMISO PERO NO DESCUENTO YA QUE LA OBLIGACION DEL CARGUE SE GENERO EN VIGENCIA DE OTRO CONTRATO | AN6: ANA MARIA ROJAS | AQ6: X | AR6: ANA MARIA ROJAS
A7: WORLD LEGAL CORPORATION SAS | B7: ID_007965549 | C7: 2025_22812760 | D7: 2691895 | E7: 11001310503420250010500 | G7: ORDINARIO LABORAL DE PRIMERA INSTANCIA | H7: 80351015 | I7: JOSE VICENTE NEUTA ZABALA | J7: Colpensiones | K7: BOGOTA | L7: SIN FALLO | N7: SIN FALLO | P7: NO | Q7: Se cargó en la plataforma ekogui la pieza procesal DEMANDA-ORDINARIA, pero es un comodín, pantallazo, o es otra pieza procesal. | AH7: ERROR | AI7: Se cargó en la plataforma ekogui la pieza procesal DEMANDA-ORDINARIA, pero es un comodín, pantallazo, o es otra pieza procesal.//////////////// | AJ7: NO PROCEDE ERROR | AK7: EL ARCHIVO DEMANDA ESTA CARGADO DESDE 2026/04/05 CON EL NOMBRE DE PDF: 01PROCESOORDINARIOLABORALDEPRIMERAINSTANCIADEMANDAYANEXOSJOSEVICENTENEUTAZABALA.pdf | AN7: ANA MARIA ROJAS | AQ7: X | AR7: ANA MARIA ROJAS
A8: WORLD LEGAL CORPORATION SAS | B8: ID_007321598 | C8: 2022_17249359 | D8: 2374270 | E8: 11001310500720220003800 | G8: ORDINARIO LABORAL DE PRIMERA INSTANCIA | H8: 17580855 | I8: MANUEL JOSE CAROPRESE MENDEZ | J8: Colpensiones | K8: BOGOTA | L8: DESFAVORABLE | M8: 4/03/2024 | N8: SIN FALLO | P8: SI | T8: SI | V8: NO | W8: Se cargó en la plataforma ekogui la pieza procesal SENTENCIA, pero es un comodín, pantallazo, o es otra pieza procesal. | AH8: ERROR | AI8: //////Se cargó en la plataforma ekogui la pieza procesal SENTENCIA, pero es un comodín, pantallazo, o es otra pieza procesal.////////// | AJ8: NO PROCEDE ERROR | AK8: EL ACTA REQUERIDA ES DE FECHA 04/03/2024, FECHA PARA LA CUAL LA FIRMA NO EJERCIA DEFENSA PARA LA ENTIDAD, POR LO TANTO GENERA COMPROMISO PERO NO DESCUENTO YA QUE LA OBLIGACION DEL CARGUE SE GENERO EN VIGENCIA DE OTRO CONTRATO | AN8: ANA MARIA ROJAS | AQ8: X | AR8: ANA MARIA ROJAS
A9: TRUJILLO POLANIA Y ASOCIADOS | B9: ID_00037146 | C9: ISS_34689 | D9: 238481 | E9: 11001310501420110046500 | G9: EJECUTIVO LABORAL | H9: 3115904 | I9: AGUSTIN FONSECA | J9: ISS | K9: BOGOTA | L9: CONTINUA CON LA EJECUCION | M9: 12/08/2011 | N9: SIN FALLO | Z9: NO | AA9: Se cargó en la plataforma ekogui la pieza procesal DEMANDA QUE DA ORIGEN AL MANDAMIENTO DE PAGO, pero es un comodín, pantallazo, o es otra pieza procesal. | AB9: SI | AD9: NO | AE9: No se cargó en la plataforma ekogui la pieza procesal EXCEPCIONES_CONTESTACION | AF9: NO | AG9: No se cargó en la plataforma ekogui la pieza procesal AUTO QUE ORDENA/NO ORDENA CONTINUAR CON LA EJECUCION. | AH9: ERROR | AI9: //////////Se cargó en la plataforma ekogui la pieza procesal DEMANDA QUE DA ORIGEN AL MANDAMIENTO DE PAGO, pero es un comodín, pantallazo, o es otra pieza procesal.////No se cargó en la plataforma ekogui la pieza procesal EXCEPCIONES_CONTESTACION//No se cargó en la plataforma ekogui la pieza procesal AUTO QUE ORDENA/NO ORDENA CONTINUAR CON LA EJECUCION. | AJ9: NO PROCEDE ERROR | AK9: EL CARGUE DE LA PIEZA MENCIONADA, NO SE DIO EN VIGENCIA DE LA FIRMA TRUJILLO POLANIA, SIN EMBARGO SE SOLICITA ACCESO AL EXPEDIENTE PARA DAR CORRECCION A LO SOLICITADO. (AUTO QUE LIBRA MANDAMIENTO DE PAGO CON FECHA DE 16/08/2011. | AN9: ANA MARIA ROJAS | AQ9: X | AR9: ANA MARIA ROJAS
A10: WORLD LEGAL CORPORATION SAS | B10: ID_007148863 | C10: 2022_1533276 | D10: 2265978 | E10: 11001310501120200025501 | G10: ORDINARIO LABORAL DE PRIMERA INSTANCIA | H10: 19307013 | I10: CESAR AUGUSTO MELO BELLO | J10: Colpensiones | K10: BOGOTA | L10: DESFAVORABLE | M10: 5/09/2023 | N10: DESFAVORABLE | O10: 31/05/2024 | P10: SI | T10: SI | V10: NO | W10: Se cargó en la plataforma ekogui la pieza procesal SENTENCIA de forma incompleta. | Y10: SI | AH10: ERROR | AI10: //////Se cargó en la plataforma ekogui la pieza procesal SENTENCIA de forma incompleta.//SI//////// | AJ10: NO PROCEDE ERROR | AK10: LA PIEZA PROCESAL ESTA CARGADA DESDE:2024/06/12 -SENTENCIA- 11001310501120200025501.pdf Y 2023/11/07-SENTENCIA- 11001310501120200025501.pdf// CABE INDICAR QUE LA PIEZA PROCESAS CARGADA EN SENTENCIA DE 1RA SE CARGO COMO REPOSA EN EL EXPEDIENTE, Y DE ESA MISMA FORMA SE REMITIO AL TRIBUNAL Y EL TRIBUNAL LE DIO TRAMITE SIN FIRMA | AN10: ANA MARIA ROJAS | AQ10: X | AR10: ANA MARIA ROJAS
A11: WORLD LEGAL CORPORATION SAS | B11: ID_00345507 | C11: 2017_7977748 | D11: 1050504 | E11: 11001310503520170004500 | G11: EJECUTIVO LABORAL | H11: 13004846 | I11: BENJAMIN GARRIDO TORRES | J11: Colpensiones | K11: BOGOTA | L11: CONTINUA CON LA EJECUCION | M11: 17/01/2018 | N11: SIN FALLO | Z11: NO | AA11: No se cargó en la plataforma ekogui la pieza procesal DEMANDA QUE DA ORIGEN AL MANDAMIENTO DE PAGO. | AB11: SI | AD11: SI | AF11: SI | AH11: ERROR | AI11: //////////No se cargó en la plataforma ekogui la pieza procesal DEMANDA QUE DA ORIGEN AL MANDAMIENTO DE PAGO.////// | AJ11: NO PROCEDE ERROR | AK11: LA DEMANDA EJECUTIVA ESTA CARGADA DESDE 01/08/2017 en el folio 6 y 7, en el pdf llamado: "PROCESO (MP)DTE: BENJAMIN GARRIDO TORRESDDO: COLPENSIONES .pdf" | AN11: ANA MARIA ROJAS | AQ11: X | AR11: ANA MARIA ROJAS
A12: TRUJILLO POLANIA Y ASOCIADOS | B12: ID_00086820 | C12: 2013_4144956 | D12: 1166392 | E12: 11001310501420130036600 | G12: EJECUTIVO LABORAL | H12: 20152709 | I12: MARGARITA ANGEL RINCON | J12: COLPENSIONES | K12: BOGOTA | L12: CONTINUA CON LA EJECUCION | M12: 27/06/2014 | N12: SIN FALLO | Z12: NO | AA12: Se cargó en la plataforma ekogui la pieza procesal DEMANDA QUE DA ORIGEN AL MANDAMIENTO DE PAGO, pero es un comodín, pantallazo, o es otra pieza procesal. | AB12: SI | AH12: ERROR | AI12: //////////Se cargó en la plataforma ekogui la pieza procesal DEMANDA QUE DA ORIGEN AL MANDAMIENTO DE PAGO, pero es un comodín, pantallazo, o es otra pieza procesal.////// | AJ12: NO PROCEDE ERROR | AK12: EL CARGUE DE LA PIEZA MENCIONADA, NO SE DIO EN VIGENCIA DE LA FIRMA TRUJILLO POLANIA, SIN EMBARGO SE SOLICITA ACCESO AL EXPEDIENTE PARA DAR CORRECCION A LO SOLICITADO. (SE CARGAN TODAS LAS PIEZAS REQUERIDAS) | AN12: ANA MARIA ROJAS | AQ12: X | AR12: ANA MARIA ROJAS
A13: TRUJILLO POLANIA Y ASOCIADOS | B13: ID_00111676 | C13: 2014_811518 | D13: 1222944 | E13: 11001310501420130054600 | G13: EJECUTIVO LABORAL | H13: 7934 | I13: GUILLERMO GARCIA GUAJE | J13: COLPENSIONES | K13: BOGOTA | L13: CONTINUA CON LA EJECUCION | M13: 8/05/2014 | N13: SIN FALLO | Z13: NO | AA13: No se cargó en la plataforma ekogui la pieza procesal DEMANDA QUE DA ORIGEN AL MANDAMIENTO DE PAGO. | AB13: SI | AH13: ERROR | AI13: //////////No se cargó en la plataforma ekogui la pieza procesal DEMANDA QUE DA ORIGEN AL MANDAMIENTO DE PAGO.////// | AJ13: NO PROCEDE ERROR | AK13: EL CARGUE DE LA PIEZA MENCIONADA, NO SE DIO EN VIGENCIA DE LA FIRMA TRUJILLO POLANIA, SIN EMBARGO SE SOLICITA ACCESO AL EXPEDIENTE PARA DAR CORRECCION A LO SOLICITADO. (SE CARGAN TODAS LAS PIEZAS REQUERIDAS) | AN13: ANA MARIA ROJAS | AQ13: X | AR13: ANA MARIA ROJAS
A14: TRUJILLO POLANIA Y ASOCIADOS | B14: ID_00113579 | C14: 2014_1180011 | D14: 1273211 | E14: 11001310500920100014500 | G14: EJECUTIVO LABORAL | H14: 41434053 | I14: AURA CECILIA RODRIGUEZ GARCIA | J14: COLPENSIONES | K14: BOGOTA | L14: CONTINUA CON LA EJECUCION | M14: 15/11/2011 | N14: SIN FALLO | Z14: NO | AA14: Se cargó en la plataforma ekogui la pieza procesal DEMANDA QUE DA ORIGEN AL MANDAMIENTO DE PAGO, pero es un comodín, pantallazo, o es otra pieza procesal. | AB14: NO | AC14: No se cargó en la plataforma ekogui la pieza procesal MANDAMIENTO DE PAGO. | AH14: ERROR | AI14: //////////Se cargó en la plataforma ekogui la pieza procesal DEMANDA QUE DA ORIGEN AL MANDAMIENTO DE PAGO, pero es un comodín, pantallazo, o es otra pieza procesal.//No se cargó en la plataforma ekogui la pieza procesal MANDAMIENTO DE PAGO.//// | AJ14: NO PROCEDE ERROR | AK14: EL CARGUE DE LA PIEZA MENCIONADA, NO SE DIO EN VIGENCIA DE LA FIRMA TRUJILLO POLANIA, SIN EMBARGO SE SOLICITA ACCESO AL EXPEDIENTE PARA DAR CORRECCION A LO SOLICITADO. (SE CARGAN TODAS LAS PIEZAS REQUERIDAS) | AN14: ANA MARIA ROJAS | AQ14: X | AR14: ANA MARIA ROJAS
A15: WORLD LEGAL CORPORATION SAS | B15: ID_007748075 | C15: 2024_23901420 | D15: 2598528 | E15: 11001310502720240109300 | G15: EJECUTIVO LABORAL | H15: 51623108 | I15: MARIA EUGENIA TIBASOSA GIL | J15: Colpensiones | K15: BOGOTA | L15: SIN FALLO | N15: SIN FALLO | Z15: NO | AA15: Se cargó en la plataforma ekogui la pieza procesal DEMANDA QUE DA ORIGEN AL MANDAMIENTO DE PAGO, pero es un comodín, pantallazo, o es otra pieza procesal. | AB15: SI | AD15: SI | AF15: NO | AG15: Se cargó en la plataforma ekogui la pieza procesal AUTO QUE ORDENA/NO ORDENA CONTINUAR CON LA EJECUCION, pero es un comodín, pantallazo, o es otra pieza procesal. | AH15: ERROR | AI15: //////////Se cargó en la plataforma ekogui la pieza procesal DEMANDA QUE DA ORIGEN AL MANDAMIENTO DE PAGO, pero es un comodín, pantallazo, o es otra pieza procesal.//////Se cargó en la plataforma ekogui la pieza procesal AUTO QUE ORDENA/NO ORDENA CONTINUAR CON LA EJECUCION, pero es un comodín, pantallazo, o es otra pieza procesal. | AJ15: NO PROCEDE ERROR | AK15: LA DEMANDA EJECUTIVA ESTA CARGADA DESDE 31/03/2026 CON EL PDF DE NOMBRE: "11001310502720240109300-DEMANDA.pdf"- Y LA SENTENCIA EJECUTIVA O AUTO DE SEGUIR ADELANTE SE ENCUENTRA CARGADO DESDE EL 31/03/2026 CON EL PDF "8. ANEXO - AUTO QUE ORDENA CONTINUAR CON LA EJECUCIÓN (4).pdf" | AN15: ANA MARIA ROJAS | AQ15: X | AR15: ANA MARIA ROJAS
A16: JURISCOL ABOGADOS SAS | B16: ID_007422193 | C16: 2023_8774502 | D16: 2376987 | E16: 11001310502620220038300 | G16: ORDINARIO LABORAL DE PRIMERA INSTANCIA | H16: 4228527 | I16: JOSE ROBINSON SOTELO PAEZ | J16: Colpensiones | K16: BOGOTA | L16: FAVORABLE | M16: 26/09/2025 | N16: SIN FALLO | P16: SI | T16: SI | V16: SI | X16: NO | Y16: Se cargó en la plataforma ekogui la pieza procesal SENTENCIA de forma incompleta. | AH16: ERROR | AI16: ////////Se cargó en la plataforma ekogui la pieza procesal SENTENCIA de forma incompleta.//////// | AJ16: NO PROCEDE ERROR | AK16: NO SE HA CARGADO PIEZA PROCESAL TODA VEZ QUE NO SE HA SURTIDO SENTENCIA DE SEGUNDA INSTANCIA | AN16: ANA MARIA ROJAS | AQ16: X | AR16: ANA MARIA ROJAS
A17: WORLD LEGAL CORPORATION SAS | B17: ID_00405778 | C17: 2018_1797709 | D17: 1157695 | E17: 11001310501120170005900 | G17: EJECUTIVO LABORAL | H17: 17184679 | I17: GERMAN CEPEDA SIERRA | J17: Colpensiones | K17: BOGOTA | L17: CONTINUA CON LA EJECUCION | M17: 25/10/2019 | N17: SIN FALLO | Z17: SI | AB17: SI | AD17: NO | AE17: No se cargó en la plataforma ekogui la pieza procesal EXCEPCIONES_CONTESTACION. | AF17: NO | AG17: No se cargó en la plataforma ekogui la pieza procesal AUTO_QUE_ORDENA_CONTINUAR/NO_CONTINUAR_CON _LA_EJECUCION | AH17: ERROR | AI17: //////////////No se cargó en la plataforma ekogui la pieza procesal EXCEPCIONES_CONTESTACION.//No se cargó en la plataforma ekogui la pieza procesal AUTO_QUE_ORDENA_CONTINUAR/NO_CONTINUAR_CON _LA_EJECUCION | AJ17: NO PROCEDE ERROR | AK17: EL ARCHIVO DE EXCEPCIONES DEL EJECUTIVO ESTA CARGADO EL DIA 03/12/2021 CON EL PDF LLAMADO "11001310501120170005900 LIQUIDACIÓN CREDITO.pdf" Y EL ARCHIVO DE SENTENCIA ESTA CARGADO EL DIA 27/05/2024 CON EL PDF LLAMADO: "11001310501120170005900 - SENTENCIA.pdf" | AN17: ANA MARIA ROJAS | AQ17: X | AR17: ANA MARIA ROJAS
A18: WORLD LEGAL CORPORATION SAS | B18: ID_007248323 | C18: 2022_10261598 | D18: 2322183 | E18: 11001310503420200013200 | G18: ORDINARIO LABORAL DE PRIMERA INSTANCIA | H18: 19377551 | I18: HUMBERTO MADRID ALARCON | J18: Colpensiones | K18: BOGOTA | L18: DESFAVORABLE | M18: 4/12/2024 | N18: SIN FALLO | P18: SI | T18: SI | V18: SI | X18: NO | Y18: No se cargó en la plataforma ekogui la pieza procesal SENTENCIA. | AH18: ERROR | AI18: ////////No se cargó en la plataforma ekogui la pieza procesal SENTENCIA.//////// | AJ18: NO PROCEDE ERROR | AK18: LA PIEZA PROCESAL SENTENCIA ESTA CARGADA DESDE 19/12/2024 CON EL PDF LLAMADO: 11001310503420200013200.pdf | AN18: ANA MARIA ROJAS | AQ18: X | AR18: ANA MARIA ROJAS
A19: TRUJILLO POLANIA Y ASOCIADOS | B19: ID_00137526 | C19: 2014_5632011 | D19: 627890 | E19: 11001310500820140009800 | G19: EJECUTIVO LABORAL | H19: 4321352 | I19: JUAN DE DIOS OCHOA DAZA | J19: COLPENSIONES | K19: BOGOTA | L19: CONTINUA CON LA EJECUCION | M19: 17/08/2017 | N19: SIN FALLO | Z19: SI | AB19: NO | AC19: No se cargó en la plataforma ekogui la pieza procesal MANDAMIENTO DE PAGO. | AD19: NO | AE19: No se cargó en la plataforma ekogui la pieza procesal EXCEPCIONES_CONTESTACION | AF19: NO | AG19: No se cargó en la plataforma ekogui la pieza procesal AUTO_QUE_ORDENA_CONTINUAR/NO_CONTINUAR_CON _LA_EJECUCION | AH19: ERROR | AI19: ////////////No se cargó en la plataforma ekogui la pieza procesal MANDAMIENTO DE PAGO.//No se cargó en la plataforma ekogui la pieza procesal EXCEPCIONES_CONTESTACION//No se cargó en la plataforma ekogui la pieza procesal AUTO_QUE_ORDENA_CONTINUAR/NO_CONTINUAR_CON _LA_EJECUCION | AJ19: NO PROCEDE ERROR | AK19: EL CARGUE DE LA PIEZA MENCIONADA, NO SE DIO EN VIGENCIA DE LA FIRMA TRUJILLO POLANIA, SIN EMBARGO SE SOLICITA ACCESO AL EXPEDIENTE PARA DAR CORRECCION A LO SOLICITADO. (SE CARGAN TODAS LAS PIEZAS REQUERIDAS) | AN19: ANA MARIA ROJAS | AQ19: X | AR19: ANA MARIA ROJAS
A20: VENCE SALAMANCA LAWYERS GROUP SAS | B20: ID_007442143 | C20: 2023_11219374 | D20: 2451719 | E20: 11001310504020210044700 | G20: ORDINARIO LABORAL DE PRIMERA INSTANCIA | H20: 35331445 | I20: MARIA LIDA ESPERANZA HERNANDEZ ESCOBAR | J20: Colpensiones | K20: BOGOTA | L20: SIN FALLO | N20: SIN FALLO | P20: SI | R20: NO | S20: No se cargó en la plataforma ekogui la pieza procesal ACTA DE AUDIENCIA. | T20: SI | V20: NO | W20: No se cargó en la plataforma ekogui la pieza procesal SENTENCIA. | AH20: ERROR | AI20: //No se cargó en la plataforma ekogui la pieza procesal ACTA DE AUDIENCIA.////No se cargó en la plataforma ekogui la pieza procesal SENTENCIA.////////// | AJ20: NO PROCEDE ERROR | AK20: LA PIEZA PROCESAL "ACTA DE AUDIENCIA" NO ESTÁ EN LOS LINEAMIENTOS DE LA ANS2 Y NO ES OBJETO DE AUDITORIA, EN EL PROCESO NO SE PROFIRIÓ SENTENCIA, TERMINÓ ANORMALMENTE MEDIANTE AUTO | AM20: GENERA DESCUENTO | AN20: ANA MARIA ROJAS | AQ20: X | AR20: ANA MARIA ROJAS
A21: TRUJILLO POLANIA Y ASOCIADOS | B21: ID_00146806 | C21: 2014_7093360 | D21: 626545 | E21: 11001310500920070098700 | G21: EJECUTIVO LABORAL | H21: 17089621 | I21: JOSE VICENTE ROJAS MORENO | J21: COLPENSIONES | K21: BOGOTA | L21: CONTINUA CON LA EJECUCION | M21: 25/11/2010 | N21: SIN FALLO | Z21: NO | AA21: No se cargó en la plataforma ekogui la pieza procesal DEMANDA QUE DA ORIGEN AL MANDAMIENTO DE PAGO. | AB21: SI | AD21: NO | AE21: No se cargó en la plataforma ekogui la pieza procesal EXCEPCIONES_CONTESTACION | AF21: NO | AG21: No se cargó en la plataforma ekogui la pieza procesal AUTO_QUE_ORDENA_CONTINUAR/NO_CONTINUAR_CON _LA_EJECUCION | AH21: ERROR | AI21: //////////No se cargó en la plataforma ekogui la pieza procesal DEMANDA QUE DA ORIGEN AL MANDAMIENTO DE PAGO.////No se cargó en la plataforma ekogui la pieza procesal EXCEPCIONES_CONTESTACION//No se cargó en la plataforma ekogui la pieza procesal AUTO_QUE_ORDENA_CONTINUAR/NO_CONTINUAR_CON _LA_EJECUCION | AJ21: NO PROCEDE ERROR | AK21: EL CARGUE DE LA PIEZA MENCIONADA, NO SE DIO EN VIGENCIA DE LA FIRMA TRUJILLO POLANIA, SIN EMBARGO SE SOLICITA ACCESO AL EXPEDIENTE PARA DAR CORRECCION A LO SOLICITADO. (SE CARGAN TODAS LAS PIEZAS REQUERIDAS) | AN21: ANA MARIA ROJAS | AQ21: X | AR21: ANA MARIA ROJAS
A22: TABOR ASESORES LEGALES SAS | B22: ID_007594810 | C22: 2024_5871472 | D22: 2460415 | E22: 11001310500120230009200 | G22: ORDINARIO LABORAL DE PRIMERA INSTANCIA | H22: 12533791 | I22: CESAR AUGUSTO BOJATO PEREZ | J22: Colpensiones | K22: BOGOTA | L22: SIN FALLO | N22: SIN FALLO | P22: NO | Q22: Se cargó en la plataforma ekogui la pieza procesal DEMANDA-ORDINARIA, pero no fue cargada por parte de firma que representa a Colpensiones. | T22: SI | AH22: ERROR | AI22: Se cargó en la plataforma ekogui la pieza procesal DEMANDA-ORDINARIA, pero no fue cargada por parte de firma que representa a Colpensiones.//////////////// | AJ22: NO PROCEDE ERROR | AK22: EL PROCESO FUE CREADO EN EKOGUI 2023-08-13, COLPENSIONES FUE NOTIFICADO 2024-04-02. LO QUE SIGNIFICA QUE COLPENSIONES NO LE ES POSIBLE CREAR OTRO PROCESO EN EL APLICATIVO, SINO QUE SE VINCULA ES MAS NO ES POSIBLE NI EDITAR EL DOCUMENTO | AN22: ANA MARIA ROJAS | AQ22: X | AR22: ANA MARIA ROJAS
A23: WORLD LEGAL CORPORATION SAS | B23: ID_007993968 | C23: 2025_25870069 | D23: 2706234 | E23: 11001310503320190038900 | G23: EJECUTIVO LABORAL | H23: 4191189 | I23: JOSE SAUL FLECHAS VELASCO | J23: Colpensiones | K23: BOGOTA | L23: SIN FALLO | N23: SIN FALLO | Z23: SI | AB23: NO | AC23: Se cargó en la plataforma ekogui la pieza procesal MANDAMIENTO DE PAGO, pero es un comodín, pantallazo, o es otra pieza procesal. | AD23: SI | AH23: ERROR | AI23: ////////////Se cargó en la plataforma ekogui la pieza procesal MANDAMIENTO DE PAGO, pero es un comodín, pantallazo, o es otra pieza procesal.//// | AJ23: NO PROCEDE ERROR | AK23: EL ARCHIVO MANDAMIENTO DE PAGO ESTA CARGADO DESDE EL DIA 17/12/2025 CON EL PDF LLAMADO: " 2025_25870069-NOTIFICACION.pdf" | AN23: ANA MARIA ROJAS | AQ23: X | AR23: ANA MARIA ROJAS
A24: TRUJILLO POLANIA Y ASOCIADOS | B24: ID_00174266 | C24: 2015_2212576 | D24: 638321 | E24: 11001310500920140052400 | G24: EJECUTIVO LABORAL | H24: 8999990823 | I24: GRUPO ENERGÍA DE BOGOTA SA ESP | J24: COLPENSIONES | K24: BOGOTA | L24: CONTINUA CON LA EJECUCION | M24: 17/09/2015 | N24: SIN FALLO | Z24: SI | AB24: NO | AC24: Se cargó en la plataforma ekogui la pieza procesal MANDAMIENTO DE PAGO, pero es un comodín, pantallazo, o es otra pieza procesal. | AD24: NO | AE24: No se cargó en la plataforma ekogui la pieza procesal EXCEPCIONES_CONTESTACION | AF24: NO | AG24: No se cargó en la plataforma ekogui la pieza procesal AUTO_QUE_ORDENA_CONTINUAR/NO_CONTINUAR_CON _LA_EJECUCION | AH24: ERROR | AI24: ////////////Se cargó en la plataforma ekogui la pieza procesal MANDAMIENTO DE PAGO, pero es un comodín, pantallazo, o es otra pieza procesal.//No se cargó en la plataforma ekogui la pieza procesal EXCEPCIONES_CONTESTACION//No se cargó en la plataforma ekogui la pieza procesal AUTO_QUE_ORDENA_CONTINUAR/NO_CONTINUAR_CON _LA_EJECUCION | AJ24: NO PROCEDE ERROR | AK24: EL CARGUE DE LA PIEZA MENCIONADA, NO SE DIO EN VIGENCIA DE LA FIRMA TRUJILLO POLANIA, SIN EMBARGO SE SOLICITA ACCESO AL EXPEDIENTE PARA DAR CORRECCION A LO SOLICITADO. (SE CARGAN TODAS LAS PIEZAS REQUERIDAS) | AN24: ANA MARIA ROJAS | AQ24: X | AR24: ANA MARIA ROJAS
A25: TRUJILLO POLANIA Y ASOCIADOS | B25: ID_00183076 | C25: 2015_3957368 | D25: 1144539 | E25: 11001310501620130057500 | G25: EJECUTIVO LABORAL | H25: 26053 | I25: DOMINGO TORRES CASTEBLANCO | J25: COLPENSIONES | K25: BOGOTA | L25: CONTINUA CON LA EJECUCION | M25: 24/07/2015 | N25: SIN FALLO | Z25: SI | AB25: NO | AC25: Se cargó en la plataforma ekogui la pieza procesal MANDAMIENTO DE PAGO, pero es un comodín, pantallazo, o es otra pieza procesal. | AD25: NO | AE25: No se cargó en la plataforma ekogui la pieza procesal EXCEPCIONES_CONTESTACION | AF25: NO | AG25: No se cargó en la plataforma ekogui la pieza procesal AUTO_QUE_ORDENA_CONTINUAR/NO_CONTINUAR_CON _LA_EJECUCION | AH25: ERROR | AI25: ////////////Se cargó en la plataforma ekogui la pieza procesal MANDAMIENTO DE PAGO, pero es un comodín, pantallazo, o es otra pieza procesal.//No se cargó en la plataforma ekogui la pieza procesal EXCEPCIONES_CONTESTACION//No se cargó en la plataforma ekogui la pieza procesal AUTO_QUE_ORDENA_CONTINUAR/NO_CONTINUAR_CON _LA_EJECUCION | AJ25: NO PROCEDE ERROR | AK25: EL CARGUE DE LA PIEZA MENCIONADA, NO SE DIO EN VIGENCIA DE LA FIRMA TRUJILLO POLANIA, SIN EMBARGO SE SOLICITA ACCESO AL EXPEDIENTE PARA DAR CORRECCION A LO SOLICITADO. (SE CARGAN TODAS LAS PIEZAS REQUERIDAS) | AN25: ANA MARIA ROJAS | AQ25: X | AR25: ANA MARIA ROJAS
A26: TABOR ASESORES LEGALES SAS | B26: ID_007084909 | C26: 2021_11469493 | D26: 2238406 | E26: 11001310500420210042500 | G26: ORDINARIO LABORAL DE PRIMERA INSTANCIA | H26: 73095252 | I26: EFRAIN OROZCO PEREZ | J26: Colpensiones | K26: BOGOTA | L26: DESFAVORABLE | M26: 30/05/2023 | N26: DESFAVORABLE | O26: 29/04/2025 | P26: SI | T26: NO | U26: No se cargó en la plataforma ekogui la pieza procesal CONTESTACION DE LA DEMANDA. | V26: NO | W26: No se cargó en la plataforma ekogui la pieza procesal SENTENCIA. | X26: SI | AH26: ERROR | AI26: ////No se cargó en la plataforma ekogui la pieza procesal CONTESTACION DE LA DEMANDA.//No se cargó en la plataforma ekogui la pieza procesal SENTENCIA.////////// | AJ26: NO PROCEDE ERROR | AK26: NO ES SUSCEPTIBLE DE AUDITORIA POR CUANTO SE ENCUENTRA TERMINADO EN EKOGUI DESDE EL 2025-12-18 | AN26: ANA MARIA ROJAS | AQ26: X | AR26: ANA MARIA ROJAS
A27: TRUJILLO POLANIA Y ASOCIADOS | B27: ID_00185855 | C27: 2015_4519342 | D27: 922861 | E27: 11001310500820140054600 | G27: EJECUTIVO LABORAL | H27: 19218195 | I27: HECTOR EMILIO RAMIREZ PEÑALOZA | J27: COLPENSIONES | K27: BOGOTA | L27: CONTINUA CON LA EJECUCION | M27: 15/12/2015 | N27: SIN FALLO | Z27: NO | AA27: Se cargó en la plataforma ekogui la pieza procesal DEMANDA QUE DA ORIGEN AL MANDAMIENTO DE PAGO, pero es un comodín, pantallazo, o es otra pieza procesal. | AB27: SI | AD27: SI | AF27: SI | AH27: ERROR | AI27: //////////Se cargó en la plataforma ekogui la pieza procesal DEMANDA QUE DA ORIGEN AL MANDAMIENTO DE PAGO, pero es un comodín, pantallazo, o es otra pieza procesal.////// | AJ27: NO PROCEDE ERROR | AK27: EL CARGUE DE LA PIEZA MENCIONADA, NO SE DIO EN VIGENCIA DE LA FIRMA TRUJILLO POLANIA, SIN EMBARGO SE SOLICITA ACCESO AL EXPEDIENTE PARA DAR CORRECCION A LO SOLICITADO. (SE CARGAN TODAS LAS PIEZAS REQUERIDAS) | AN27: ANA MARIA ROJAS | AQ27: X | AR27: ANA MARIA ROJAS
A28: WORLD LEGAL CORPORATION SAS | B28: ID_007711265 | C28: 2024_19050121 | D28: 2443540 | E28: 11001310501120230005600 | G28: ORDINARIO LABORAL DE PRIMERA INSTANCIA | H28: 9655381 | I28: JAVIER MAURICIO ANGARITA VALDERRAMA | J28: Colpensiones | K28: BOGOTA | L28: SIN FALLO | N28: SIN FALLO | P28: SI | R28: NO | S28: Se cargó en la plataforma ekogui la pieza procesal ACTA DE AUDIENCIA, pero no fue cargada por parte de firma que representa a Colpensiones. | T28: SI | V28: SI | AH28: ERROR | AI28: //Se cargó en la plataforma ekogui la pieza procesal ACTA DE AUDIENCIA, pero no fue cargada por parte de firma que representa a Colpensiones.////////////// | AJ28: NO PROCEDE ERROR | AK28: LA PIEZA PROCESAL DE ACTA DE AUDIENCIA DONDE SE LLEVO A CABO EL FALLO ESTA CARGADO DESDE: 2026/04/05 -SENTENCIA- 11001310501120230005600 - XIMENA RAYO CALDERON.pdf// FECHA ANTES DE CORTE | AN28: ANA MARIA ROJAS | AQ28: X | AR28: ANA MARIA ROJAS
A29: VENCE SALAMANCA LAWYERS GROUP SAS | B29: ID_007374304 | C29: 2023_3831234 | D29: 2410884 | E29: 11001333704020220027900 | G29: ACCION DE NULIDAD Y RESTABLECIMIENTO DEL DERECHO | H29: 9001562642 | I29: NUEVA EMPRESA PROMOTORA DE SALUD S.A. | J29: Colpensiones | K29: BOGOTA | L29: DESFAVORABLE | M29: 18/10/2023 | N29: SIN FALLO | P29: NO | Q29: NO CARGA LA DEMANDA | T29: OK | V29: OK | X29: NO | Y29: NO SE ENCUENTRA CARGA LA SENTENCIA | AH29: ERROR | AI29: NO CARGA LA DEMANDA ////////NO SE ENCUENTRA CARGA LA SENTENCIA //////// | AJ29: NO PROCEDE ERROR | AK29: DEMANDA CARGADA DESDE EL 10/3/2023, SENTENCIA DE SEGUNDA INSTANCIA CARGADA EL 27/03/2026 | AM29: GENERA DESCUENTO | AN29: JAIME GUZMAN | AQ29: X | AR29: JAIME GUZMAN
A30: WORLD LEGAL CORPORATION SAS | B30: ID_007674554 | C30: 2024_14916127 | D30: 2560957 | E30: 11001310501120230045500 | G30: ORDINARIO LABORAL DE PRIMERA INSTANCIA | H30: 17061329 | I30: FERNANDO URIBE RODRIGUEZ | J30: Colpensiones | K30: BOGOTA | L30: DESFAVORABLE | M30: 30/10/2024 | N30: SIN FALLO | P30: OK | T30: NO | U30: Se cargó en la plataforma ekogui la pieza procesal CONTESTACION DE LA DEMANDA, pero no corresponde al proceso actual. | V30: NO | W30: Se cargó en la plataforma ekogui la pieza procesal SENTENCIA, pero no corresponde al proceso actual. | AH30: ERROR | AI30: ////Se cargó en la plataforma ekogui la pieza procesal CONTESTACION DE LA DEMANDA, pero no corresponde al proceso actual.//Se cargó en la plataforma ekogui la pieza procesal SENTENCIA, pero no corresponde al proceso actual.////////// | AJ30: NO PROCEDE ERROR | AK30: LA CONTESTACION ESTA CARGADA DESDE: 2024/08/08 -CONTESTACION DE LA DEMANDA- 11001310501120230045500.pdf Y LA SENTENCIA ESTA CARGADA DESDE 2026/04/05 -SENTENCIA- 11001310501120230045500 (1).pdf, LA SENTENCIA SE CARGO ANTES DE LA FECHA DE CORTE | AN30: JAIME GUZMAN | AQ30: X | AR30: JAIME GUZMAN
A31: VENCE SALAMANCA LAWYERS GROUP SAS | B31: ID_007635646 | C31: 2024_10673705 | D31: 2544274 | E31: 11001333704120240008400 | G31: ACCION DE NULIDAD Y RESTABLECIMIENTO DEL DERECHO | H31: 9010974735 | I31: MEDIMAS EPS SAS EN LIQUIDACION | J31: Colpensiones | K31: BOGOTA | L31: SIN FALLO | N31: SIN FALLO | P31: OK | T31: NO | U31: Se cargó en la plataforma ekogui la pieza procesal CONTESTACION DE LA DEMANDA en archivo dañado o no legible. | AH31: ERROR | AI31: ////Se cargó en la plataforma ekogui la pieza procesal CONTESTACION DE LA DEMANDA en archivo dañado o no legible.//////////// | AJ31: NO PROCEDE ERROR | AK31: CONTESTACION DE DEMANDA CARGADA Y LEGIBLE EN EKOGUI | AM31: GENERA DESCUENTO | AN31: JAIME GUZMAN | AQ31: X | AR31: JAIME GUZMAN
A32: WORLD LEGAL CORPORATION SAS | B32: ID_007822970 | C32: 2025_5791004 | D32: 2633355 | E32: 11001310503420240022800 | G32: ORDINARIO LABORAL DE PRIMERA INSTANCIA | H32: 37926344 | I32: MARIA ESTHER JEREZ CAICEDO | J32: Colpensiones | K32: BOGOTA | L32: SIN FALLO | N32: SIN FALLO | P32: NO | Q32: No se cargó en la plataforma ekogui la pieza procesal DEMANDA-ORDINARIA. | T32: OK | AH32: ERROR | AI32: No se cargó en la plataforma ekogui la pieza procesal DEMANDA-ORDINARIA.//////////////// | AJ32: NO PROCEDE ERROR | AK32: LA DEMANDA ESTA CARGADA EN EKOGUI DESDE : 2025/03/30 -DEMANDA- 2025_5791004-TRASLADO.pdf | AN32: JAIME GUZMAN | AQ32: X | AR32: JAIME GUZMAN
A33: WORLD LEGAL CORPORATION SAS | B33: ID_007864366 | C33: 2025_10941536 | D33: 2658086 | E33: 11001310502720251003900 | G33: EJECUTIVO LABORAL | H33: 63295596 | I33: MARIA CLARA NIÑO GOMEZ | J33: Colpensiones | K33: BOGOTA | L33: SIN FALLO | N33: SIN FALLO | Z33: NO | AA33: No se cargó en la plataforma ekogui la pieza procesal MANDAMIENTO DE PAGO. | AB33: OK | AD33: OK | AH33: ERROR | AI33: //////////No se cargó en la plataforma ekogui la pieza procesal MANDAMIENTO DE PAGO.////// | AJ33: NO PROCEDE ERROR | AK33: LA PIEZA MANDAMIENTO DE PAGO ESTA CARGADA DESDE 28/06/2025 CON EL NOMBRE DE PDF "2025_10941536-MANDAMIENTO DE PAGO.pdf" | AN33: JAIME GUZMAN | AQ33: X | AR33: JAIME GUZMAN
A34: WORLD LEGAL CORPORATION SAS | B34: ID_00648519 | C34: 2020_8034817 | D34: 2142929 | E34: 11001310502220190069400 | G34: EJECUTIVO LABORAL | H34: 21224119 | I34: ANA CECILIA GAMEZ FORERO | J34: Colpensiones | K34: BOGOTA | L34: CONTINUA CON LA EJECUCION | M34: 11/05/2022 | N34: SIN FALLO | Z34: NO | AA34: No se cargó en la plataforma ekogui la pieza procesal MANDAMIENTO DE PAGO. | AB34: OK | AD34: OK | AF34: OK | AH34: ERROR | AI34: //////////No se cargó en la plataforma ekogui la pieza procesal MANDAMIENTO DE PAGO.////// | AJ34: NO PROCEDE ERROR | AK34: LA PIEZA MANDAMIENTO DE PAGO ESTA CARGADA DESDE 28/08/2020 CON EL NOMBRE DE PDF "11001310502220190069400 - AUTO QUE LIBRA MANDAMIENTO.pdf" | AN34: JAIME GUZMAN | AQ34: X | AR34: JAIME GUZMAN
A35: TABOR ASESORES LEGALES SAS | B35: ID_00467580 | C35: 2018_10129949 | D35: 1290401 | E35: 11001310501820180019900 | G35: EJECUTIVO LABORAL | H35: 19228099 | I35: GILBERTO TIQUE ARAGON | J35: Colpensiones | K35: BOGOTA | L35: CONTINUA CON LA EJECUCION | M35: 25/01/2019 | N35: SIN FALLO | Z35: NO | AA35: No se cargó en la plataforma ekogui la pieza procesal DEMANDA QUE DA ORIGEN AL MANDAMIENTO DE PAGO. | AB35: OK | AD35: OK | AF35: OK | AH35: ERROR | AI35: //////////No se cargó en la plataforma ekogui la pieza procesal DEMANDA QUE DA ORIGEN AL MANDAMIENTO DE PAGO.////// | AJ35: NO PROCEDE ERROR | AK35: EL DOCUMENTO SE ENCUENTRA CARGADO Y SE DENOMINA " Demanda Anexo del radicado 20181031630822.pdf" FECHA DE CARGUE 2019/04/16 AL ABRIR EL DOCUMENTO HACE MENCION A QUE SE LIBRE MANDAMIENTO DE PAGO | AN35: JAIME GUZMAN | AQ35: X | AR35: JAIME GUZMAN
A36: VENCE SALAMANCA LAWYERS GROUP SAS | B36: ID_007921716 | C36: 2025_18056188 | D36: 2674583 | E36: 11001333501420190039800 | G36: ADMINISTRATIVO EJECUTIVO | H36: 19195127 | I36: DIEGO DE JESUS ALFONSO VENEGAS | J36: Colpensiones | K36: BOGOTA | L36: SIN FALLO | N36: SIN FALLO | Z36: NO | AA36: No se cargó en la plataforma ekogui la pieza procesal MANDAMIENTO DE PAGO. | AB36: OK | AH36: ERROR | AI36: //////////No se cargó en la plataforma ekogui la pieza procesal MANDAMIENTO DE PAGO.////// | AJ36: NO PROCEDE ERROR | AK36: MANDAMIENTO DE PAGO CARGADO EN EKOGUI DESDE EL 28/8/2025 | AM36: GENERA DESCUENTO | AN36: JAIME GUZMAN | AQ36: X | AR36: JAIME GUZMAN
A37: WORLD LEGAL CORPORATION SAS | B37: ID_007427355 | C37: 2023_9374629 | D37: 2441729 | E37: 11001310503320220061000 | G37: ORDINARIO LABORAL DE PRIMERA INSTANCIA | H37: 91214442 | I37: LUIS ADENIX PARRA BARRAGAN | J37: Colpensiones | K37: BOGOTA | L37: SIN FALLO | N37: SIN FALLO | P37: OK | T37: NO | U37: No se cargó en la plataforma ekogui la pieza procesal CONTESTACION DE LA DEMANDA. | AH37: ERROR | AI37: ////No se cargó en la plataforma ekogui la pieza procesal CONTESTACION DE LA DEMANDA.//////////// | AJ37: NO PROCEDE ERROR | AK37: SE OBSERVA EN RAMA QUE LA CONTESTACION DE LA DEMANDA SE DIO EL 30/06/2023 FECHA PARA LA CUAL LA FIRMA NO EJERCIA DEFENSA PARA LA ENTIDAD, NO OBSTANTE GENERA COMPROMISO PERO NO DESCUENTO DADO A QUE LA OBLIGACION DEL CARGUE FUE EN VIGENCIA DE OTRO CONTRATO | AN37: JAIME GUZMAN | AQ37: X | AR37: JAIME GUZMAN
A38: WORLD LEGAL CORPORATION SAS | B38: ID_007387730 | C38: 2023_5041810 | D38: 2418449 | E38: 11001310502720220027000 | G38: ORDINARIO LABORAL DE PRIMERA INSTANCIA | H38: 73082056 | I38: EUGENIO LOZANO LECOMPTE | J38: Colpensiones | K38: BOGOTA | L38: SIN FALLO | N38: SIN FALLO | P38: OK | T38: OK | V38: NO | W38: No se cargó en la plataforma ekogui la pieza procesal SENTENCIA. | X38: NO | Y38: No se cargó en la plataforma ekogui la pieza procesal SENTENCIA. | AH38: ERROR | AI38: //////No se cargó en la plataforma ekogui la pieza procesal SENTENCIA.//No se cargó en la plataforma ekogui la pieza procesal SENTENCIA.//////// | AJ38: NO PROCEDE ERROR | AK38: PROCESO SIN FALLO DE 1RA INSTANCIA, ESTA EN TRIBUNAL POR APELACION DE AUTO | AN38: JAIME GUZMAN | AQ38: X | AR38: JAIME GUZMAN
A39: VENCE SALAMANCA LAWYERS GROUP SAS | B39: ID_007496757 | C39: 2023_16712536 | D39: 2481971 | E39: 11001310504120220010000 | G39: ORDINARIO LABORAL DE PRIMERA INSTANCIA | H39: 41691019 | I39: VENTURA BARRERA DIAZ | J39: Colpensiones | K39: BOGOTA | L39: SIN FALLO | N39: SIN FALLO | P39: OK | T39: OK | V39: NO | W39: No se cargó en la plataforma ekogui la pieza procesal SENTENCIA. | AH39: ERROR | AI39: //////No se cargó en la plataforma ekogui la pieza procesal SENTENCIA.////////// | AJ39: NO PROCEDE ERROR | AK39: SENTENCIA CARGADA EN EKOGUI DENTRO DEL PERIODO DE FACTURACION EL 07/04/2026 | AM39: GENERA DESCUENTO | AN39: JAIME GUZMAN | AQ39: X | AR39: JAIME GUZMAN
A40: WORLD LEGAL CORPORATION SAS | B40: ID_007396404 | C40: 2023_5842142 | D40: 2418490 | E40: 11001310502020220037001 | G40: ORDINARIO LABORAL DE PRIMERA INSTANCIA | H40: 79355995 | I40: EDGAR FERNANDO ALONSO MASMELA | J40: Colpensiones | K40: BOGOTA | L40: DESFAVORABLE | M40: 13/03/2024 | N40: SIN FALLO | P40: OK | T40: OK | V40: OK | X40: NO | Y40: No se cargó en la plataforma ekogui la pieza procesal SENTENCIA. | AH40: ERROR | AI40: ////////No se cargó en la plataforma ekogui la pieza procesal SENTENCIA.//////// | AJ40: NO PROCEDE ERROR | AK40: LA PIEZA PROCESAL SENTENCIA ESTA CARGADA DESDE 2024/04/23 CON EL PDF LLAMADO: 11001310502020220037001.pdf | AN40: JAIME GUZMAN | AQ40: X | AR40: JAIME GUZMAN
...

Sheet Hoja2
A1: FIRMA | B1: ID_PROCESOS | C1: NO_BIZAGI | D1: ID_EKOGUI | E1: DIGITOS_23 | F1: 21 DIG | G1: TIPO_PROCESO | H1: IDENTIFICACION_DEMANDANTE | I1: NOMBRE_DEMANDANTE | J1: DEMANDADO | K1: REGIONAL | L1: SENTIDO_FALLO_1INSTANCIA | M1: FECHA_FALLO_1INSTANCIA | N1: SENTIDO_FALLO_2INSTANCIA | O1: FECHA_FALLO_2INSTANCIA | P1: DEMANDA | Q1: OBSERVACIÓN DEMANDA | R1: ACTA_DE_AUDIENCIA | S1: OBSERVACIÓN ACTA_DE_AUDIENCIA | T1: CONTESTACION_DE_DEMANDA | U1: OBSERVACIÓN CONTESTACION_DE_DEMANDA | V1: SENTENCIA_PRIMERA_INSTANCIA | W1: OBSERVACIÓN SENTENCIA_PRIMERA_INSTANCIA | X1: SENTENCIA_SEGUNDA_INSTANCIA | Y1: OBSERVACIÓN SENTENCIA_SEGUNDA_INSTANCIA | Z1: DEMANDA | AA1: OBSERVACIÓN DEMANDA | AB1: MANDAMIENTO_DE_PAGO | AC1: OBSERVACIÓN MANDAMIENTO_DE_PAGO | AD1: EXCEPCIONES_CONTESTACION | AE1: OBSERVACIÓN EXCEPCIONES_CONTESTACION | AF1: AUTO_QUE_ORDENA_CONTINUAR/NO_CONTINUAR_CON _LA_EJECUCION | AG1: OBSERVACIÓN AUTO_QUE_ORDENA_CONTINUAR/NO_CONTINUAR_CON _LA_EJECUCION | AH1: VALIDACIÓN | AI1: OBSERVACIÓN ERROR | AJ1: PROCEDE / NO PROCEDE ERROR | AK1: RAZÓN POR LA CUAL NO PROCEDE | AL1: OBSERVACIÓN REGIONAL | AM1: CONCLUSIÓN | AN1: ENCARGADO | AO1: ACTUALIZACION
A2: UNION TEMPORAL SUPRA LEGAL | B2: ID_007564982 | C2: 2024_2796587 | D2: 2515790 | E2: 05001310501920240001100 | G2: ORDINARIO LABORAL DE PRIMERA INSTANCIA | H2: 3228672 | I2: GUSTAVO ALONSO RESTREPO MOLINA | J2: Colpensiones | K2: ANTIOQUIA | L2: FAVORABLE | M2: 30/07/2024 | N2: FAVORABLE | O2: 22/04/2025 | AP2: DANIELA | AQ2: OK
A3: UNION TEMPORAL VILLEGAS CONSULTORES JURIDICOS | B3: ID_007806569 | C3: 2025_3193558 | D3: 2624776 | E3: 05001410501020240054800 | G3: ORDINARIO LABORAL DE UNICA INSTANCIA | H3: 70085715 | I3: TEOBALDO ENRIQUE CABRERA LUNA | J3: Colpensiones | K3: ANTIOQUIA | L3: SIN FALLO | N3: SIN FALLO | AP3: DANIELA | AQ3: OK
A4: UNION TEMPORAL SUPRA LEGAL | B4: ID_00329325 | C4: 2017_5172484 | D4: 1165730 | E4: 05001310500420160026700 | G4: EJECUTIVO LABORAL | H4: 3515767 | I4: FRANCISCO HERNANDO LOPEZ RAMIREZ | J4: COLPENSIONES | K4: ANTIOQUIA | L4: SIN FALLO | N4: SIN FALLO | AP4: DANIELA | AQ4: OK
A5: UNION TEMPORAL SUPRA LEGAL | B5: ID_00561372 | C5: 2019_9469591 | D5: 2037429 | E5: 05001310500420190024100 | G5: ORDINARIO LABORAL DE PRIMERA INSTANCIA | H5: 21437751 | I5: MIRYAM DEL SOCORRO MEDINA HENAO | J5: Colpensiones | K5: ANTIOQUIA | L5: DESFAVORABLE | M5: 18/09/2024 | N5: SIN FALLO | AP5: DANIELA | AQ5: OK
A6: SOLUCIONES JURIDICAS Y EMPRESARIAL SJC SAS | B6: ID_00566946 | C6: 2019_10464478 | D6: 2046297 | E6: 05001310501620190038800 | G6: ORDINARIO LABORAL DE PRIMERA INSTANCIA | H6: 43060557 | I6: BLANCA HELY RAMIREZ CORRALES | J6: Colpensiones | K6: ANTIOQUIA | L6: FAVORABLE | M6: 25/03/2021 | N6: FAVORABLE | O6: 17/02/2022 | AP6: DANIELA | AQ6: OK
A7: SOLUCIONES JURIDICAS Y EMPRESARIAL SJC SAS | B7: ID_007424507 | C7: 2023_9051099 | D7: 2439196 | E7: 05001310501120230003400 | G7: ORDINARIO LABORAL DE PRIMERA INSTANCIA | H7: 70553127 | I7: CESAR AUGUSTO ACOSTA TORRES | J7: Colpensiones | K7: ANTIOQUIA | L7: DESFAVORABLE | M7: 10/04/2024 | N7: DESFAVORABLE | O7: 26/07/2024 | AP7: DANIELA | AQ7: OK
A8: UNION TEMPORAL VILLEGAS CONSULTORES JURIDICOS | B8: ID_007378058 | C8: 2023_4113846 | D8: 2409982 | E8: 05001310502220220017000 | G8: ORDINARIO LABORAL DE PRIMERA INSTANCIA | H8: 70061924 | I8: NORMAN RAMIRO CANO MAYA | J8: Colpensiones | K8: ANTIOQUIA | L8: DESFAVORABLE | M8: 2/04/2025 | N8: SIN FALLO | AP8: DANIELA | AQ8: OK
A9: UNION TEMPORAL VILLEGAS CONSULTORES JURIDICOS | B9: ID_007756436 | C9: 2024_24824951 | D9: 2602917 | E9: 05360310500120240032600 | G9: EJECUTIVO LABORAL | H9: 70120321 | I9: FRANCISCO FOCION MONSALVE SANCHEZ | J9: Colpensiones | K9: ANTIOQUIA | L9: CONTINUA CON LA EJECUCION | M9: 6/03/2025 | N9: SIN FALLO | AP9: DANIELA | AQ9: OK
A10: WISS CONSULTORIA JURIDICA SAS | B10: ID_007822180 | C10: 2025_5661285 | D10: 2632000 | E10: 05001410501220240028100 | G10: ORDINARIO LABORAL DE UNICA INSTANCIA | H10: 14248525 | I10: JAIME DANILO VALENCIA CARDONA | J10: Colpensiones | K10: ANTIOQUIA | L10: SIN FALLO | N10: SIN FALLO | AP10: DANIELA | AQ10: OK
A11: UNION TEMPORAL SUPRA LEGAL | B11: ID_00306769 | C11: 2017_1149307 | D11: 981238 | E11: 05001310500420150040100 | G11: EJECUTIVO LABORAL | H11: 32429719 | I11: ANGELA ALICIA ROJAS ROJAS | J11: COLPENSIONES | K11: ANTIOQUIA | L11: CONTINUA CON LA EJECUCION | M11: 21/03/2017 | N11: SIN FALLO | AP11: DANIELA | AQ11: OK
A12: UNION TEMPORAL SUPRA LEGAL | B12: ID_007064460 | C12: 2021_9815582 | D12: 2230207 | E12: 05001310502420210020300 | G12: ORDINARIO LABORAL DE PRIMERA INSTANCIA | H12: 32345404 | I12: LUZ AZUCENA MUNERA SANTA | J12: Colpensiones | K12: ANTIOQUIA | L12: SIN FALLO | N12: SIN FALLO | AP12: DANIELA | AQ12: OK
A13: SOLUCIONES JURIDICAS Y EMPRESARIAL SJC SAS | B13: ID_007738587 | C13: 2024_22895026 | D13: 2593362 | E13: 05001310502220240011400 | G13: ORDINARIO LABORAL DE PRIMERA INSTANCIA | H13: 70054604 | I13: OMAR DE JESUS VANEGAS RIOS | J13: Colpensiones | K13: ANTIOQUIA | L13: SIN FALLO | N13: SIN FALLO | AP13: DANIELA | AQ13: OK
A14: SOLUCIONES JURIDICAS Y EMPRESARIAL SJC SAS | B14: ID_007759012 | C14: 2024_25096128 | D14: 2604700 | E14: 05001310500320240004500 | G14: ORDINARIO LABORAL DE PRIMERA INSTANCIA | H14: 70564222 | I14: JUAN GUILLERMO BUSTAMANTE CARDONA | J14: Colpensiones | K14: ANTIOQUIA | L14: SIN FALLO | N14: SIN FALLO | AP14: DANIELA | AQ14: OK
A15: UNION TEMPORAL SUPRA LEGAL | B15: ID_00282963 | C15: 2016_12441396 | D15: 1189749 | E15: 05001310500420160041200 | G15: EJECUTIVO LABORAL | H15: 8354806 | I15: CARLOS IGNACIO HENAO MEJIA | J15: COLPENSIONES | K15: ANTIOQUIA | L15: CONTINUA CON LA EJECUCION | M15: 24/05/2018 | N15: SIN FALLO | AP15: DANIELA | AQ15: OK
A16: WISS CONSULTORIA JURIDICA SAS | B16: ID_00576126 | C16: 2019_11845871 | D16: 2069339 | E16: 05001410500420190009700 | G16: EJECUTIVO LABORAL | H16: 70113412 | I16: CARLOS ALBERTO MOLINA SEGURA | J16: Colpensiones | K16: ANTIOQUIA | L16: CONTINUA CON LA EJECUCION | M16: 6/12/2019 | N16: SIN FALLO | AP16: DANIELA | AQ16: OK
A17: SOLUCIONES JURIDICAS Y EMPRESARIAL SJC SAS | B17: ID_007338795 | C17: 2022_18722231 | D17: 2385745 | E17: 05615310500120220042600 | G17: ORDINARIO LABORAL DE UNICA INSTANCIA | H17: 21873357 | I17: MARIA OMAIRA GOMEZ ARCILA | J17: Colpensiones | K17: ANTIOQUIA | L17: SIN FALLO | N17: SIN FALLO | AP17: DANIELA | AQ17: OK
A18: SOLUCIONES JURIDICAS Y EMPRESARIAL SJC SAS | B18: ID_007583300 | C18: 2024_4670125 | D18: 2523818 | E18: 05001310502020240003300 | G18: ORDINARIO LABORAL DE PRIMERA INSTANCIA | H18: 8226272 | I18: JESUS ANGEL CORRALES COSSIO | J18: Colpensiones | K18: ANTIOQUIA | L18: SIN FALLO | N18: SIN FALLO | AP18: DANIELA | AQ18: OK
A19: UNION TEMPORAL SUPRA LEGAL | B19: ID_007053564 | C19: 2021_9068082 | D19: 2225276 | E19: 05001310502420210015300 | G19: ORDINARIO LABORAL DE PRIMERA INSTANCIA | H19: 15350140 | I19: JOSE HUBERTO TORO MORALES | J19: Colpensiones | K19: ANTIOQUIA | L19: SIN FALLO | N19: SIN FALLO | AP19: DANIELA | AQ19: OK
A20: SOLUCIONES JURIDICAS Y EMPRESARIAL SJC SAS | B20: ID_007625594 | C20: 2024_9676910 | D20: 2540915 | E20: 05001310501620230028600 | G20: ORDINARIO LABORAL DE PRIMERA INSTANCIA | H20: 39747890 | I20: NIDIA RAMIREZ CASTRO | J20: Colpensiones | K20: ANTIOQUIA | L20: SIN FALLO | N20: SIN FALLO | AP20: DANIELA | AQ20: OK
A21: UNION TEMPORAL VILLEGAS CONSULTORES JURIDICOS | B21: ID_00275728 | C21: 2016_10698747 | D21: 1036249 | E21: 05045310500120160127300 | G21: ORDINARIO LABORAL DE PRIMERA INSTANCIA | H21: 39317991 | I21: MARIA EUGENIA FAJARDO GOMEZ | J21: COLPENSIONES | K21: ANTIOQUIA | L21: SIN FALLO | N21: SIN FALLO | AP21: DANIELA | AQ21: OK
A22: UNION TEMPORAL SUPRA LEGAL | B22: ID_00394325 | C22: 2018_524561 | D22: 1138266 | E22: 05001310500420170079500 | G22: EJECUTIVO LABORAL | H22: 3336421 | I22: JAIME JARAMILLO PANESO | J22: Colpensiones | K22: ANTIOQUIA | L22: CONTINUA CON LA EJECUCION | M22: 7/05/2019 | N22: SIN FALLO | AP22: DANIELA | AQ22: OK
A23: WISS CONSULTORIA JURIDICA SAS | B23: ID_00296660 | C23: 2013_4657830 | D23: 536851 | E23: 05001410500520130029800 | G23: EJECUTIVO LABORAL | H23: 32077697 | I23: MARIA UBALDINA BEDOYA ALVAREZ | J23: COLPENSIONES | K23: ANTIOQUIA | L23: CONTINUA CON LA EJECUCION | M23: 6/09/2013 | N23: SIN FALLO | AP23: DANIELA | AQ23: OK
A24: UNION TEMPORAL VILLEGAS CONSULTORES JURIDICOS | B24: ID_007216490 | C24: 2022_7086031 | D24: 2304431 | E24: 05001310501320220015400 | G24: ORDINARIO LABORAL DE PRIMERA INSTANCIA | H24: 21851570 | I24: LUZ MARINA GAVIRIA ACOSTA | J24: Colpensiones | K24: ANTIOQUIA | L24: DESFAVORABLE | M24: 28/02/2023 | N24: SIN FALLO | AP24: DANIELA | AQ24: OK
A25: UNION TEMPORAL VILLEGAS CONSULTORES JURIDICOS | B25: ID_007626617 | C25: 2024_9783363 | D25: 2540198 | E25: 05001310501820240006500 | G25: ORDINARIO LABORAL DE PRIMERA INSTANCIA | H25: 42892748 | I25: CLAUDIA CECILIA ARANGO SALAZAR | J25: Colpensiones | K25: ANTIOQUIA | L25: DESFAVORABLE | M25: 6/12/2024 | N25: SIN FALLO | AP25: DANIELA | AQ25: OK
A26: SOLUCIONES JURIDICAS Y EMPRESARIAL SJC SAS | B26: ID_007530947 | C26: 2023_19468439 | D26: 2500673 | E26: 05001310502720230033000 | G26: ORDINARIO LABORAL DE PRIMERA INSTANCIA | H26: 18005117 | I26: ANDRES EMILIO ARCHBOLD BRYAN | J26: Colpensiones | K26: ANTIOQUIA | L26: DESFAVORABLE | M26: 19/02/2024 | N26: SIN FALLO | AP26: DANIELA | AQ26: OK
A27: SOLUCIONES JURIDICAS Y EMPRESARIAL SJC SAS | B27: ID_007210966 | C27: 2022_6657368 | D27: 2300768 | E27: 05001310500620220003200 | G27: ORDINARIO LABORAL DE PRIMERA INSTANCIA | H27: 51852650 | I27: SILIA JAQUELINE CAICEDO | J27: Colpensiones | K27: ANTIOQUIA | L27: SIN FALLO | N27: SIN FALLO | P27: SI | T27: SI | V27: NO APLICA | X27: NO APLICA | AP27: MANUEL | AQ27: OK
A28: SOLUCIONES JURIDICAS Y EMPRESARIAL SJC SAS | B28: ID_007411772 | C28: 2023_7511587 | D28: 2431300 | E28: 05088310500220220008800 | G28: ORDINARIO LABORAL DE PRIMERA INSTANCIA | H28: 79590025 | I28: LUIS FERNANDO CELY ROMERO | J28: Colpensiones | K28: ANTIOQUIA | L28: FAVORABLE | M28: 30/01/2024 | N28: SIN FALLO | P28: SI | T28: SI | V28: SI | X28: NO APLICA | AP28: MANUEL | AQ28: OK
A29: UNION TEMPORAL VILLEGAS CONSULTORES JURIDICOS | B29: ID_007750470 | C29: 2024_24144753 | D29: 2600578 | E29: 05001310500820240016800 | G29: ORDINARIO LABORAL DE PRIMERA INSTANCIA | H29: 32443110 | I29: MARIA DORA OROZCO CORTES | J29: Colpensiones | K29: ANTIOQUIA | L29: SIN FALLO | N29: SIN FALLO | P29: SI | T29: SI | V29: NO APLICA | X29: NO APLICA | AP29: MANUEL | AQ29: OK
A30: SOLUCIONES JURIDICAS Y EMPRESARIAL SJC SAS | B30: ID_007228829 | C30: 2022_8404763 | D30: 2313417 | E30: 05001310501120220006500 | G30: ORDINARIO LABORAL DE PRIMERA INSTANCIA | H30: 73112048 | I30: RUBEN NICOLAS POLO ARRAZOLA | J30: Colpensiones | K30: ANTIOQUIA | L30: DESFAVORABLE | M30: 5/12/2023 | N30: DESFAVORABLE | O30: 30/08/2024 | P30: SI | T30: SI | V30: SI | X30: SI | AP30: MANUEL | AQ30: OK
A31: UNION TEMPORAL VILLEGAS CONSULTORES JURIDICOS | B31: ID_007223060 | C31: 2022_7788903 | D31: 2311352 | E31: 05001310501020210039400 | G31: EJECUTIVO LABORAL | H31: 98714518 | I31: TERESA DE JESUS USUGA USUGA | J31: Colpensiones | K31: ANTIOQUIA | L31: CONTINUA CON LA EJECUCION | M31: 11/04/2023 | N31: SIN FALLO | Z31: SI | AB31: SI | AD31: SI | AF31: SI | AP31: MANUEL | AQ31: OK
A32: SOLUCIONES JURIDICAS Y EMPRESARIAL SJC SAS | B32: ID_00557279 | C32: 2019_8843132 | D32: 2030574 | E32: 05001310501120180029100 | G32: ORDINARIO LABORAL DE PRIMERA INSTANCIA | H32: 618834 | I32: LUIS IVAN ALVAREZ MESA | J32: Colpensiones | K32: ANTIOQUIA | L32: DESFAVORABLE | M32: 21/08/2024 | N32: SIN FALLO | P32: SI | T32: SI | V32: SI | X32: NO APLICA | AP32: MANUEL | AQ32: OK
A33: UNION TEMPORAL VILLEGAS CONSULTORES JURIDICOS | B33: ID_007365159 | C33: 2023_2967149 | D33: 2401828 | E33: 05001310502120230004200 | G33: ORDINARIO LABORAL DE PRIMERA INSTANCIA | H33: 16703374 | I33: RICARDO ANDRES PARDO DIAZ | J33: Colpensiones | K33: ANTIOQUIA | L33: DESFAVORABLE | M33: 25/07/2024 | N33: DESFAVORABLE | O33: 6/12/2024 | P33: SI | T33: SI | V33: SI | X33: SI | AP33: MANUEL | AQ33: OK
A34: SOLUCIONES JURIDICAS Y EMPRESARIAL SJC SAS | B34: ID_00390590 | C34: 2017_13152049 | D34: 1117349 | E34: 05001310502220170073300 | G34: ORDINARIO LABORAL DE PRIMERA INSTANCIA | H34: 22023192 | I34: LEONILDA DE JESUS CARDONA MENDOZA | J34: Colpensiones | K34: ANTIOQUIA | L34: FAVORABLE | M34: 18/10/2019 | N34: SIN FALLO | P34: SI | T34: SI | V34: SI | X34: NO APLICA | AP34: MANUEL | AQ34: OK
A35: UNION TEMPORAL SUPRA LEGAL | B35: ID_00450973 | C35: 2018_7542012 | D35: 1260234 | E35: 05001310500420140123300 | G35: EJECUTIVO LABORAL | H35: 21290134 | I35: ANA GUDIELA ALZATE GOMEZ | J35: Colpensiones | K35: ANTIOQUIA | L35: SIN FALLO | N35: SIN FALLO | Z35: SI | AB35: SI | AD35: SI | AF35: NO | AH35: ERROR | AP35: MANUEL | AQ35: OK
A36: UNION TEMPORAL SUPRA LEGAL | B36: ID_007470309 | C36: 2023_14267145 | D36: 2466722 | E36: 05001310500120230000100 | G36: ORDINARIO LABORAL DE PRIMERA INSTANCIA | H36: 70063494 | I36: FERNANDO DE JESUS RAVE RODAS | J36: Colpensiones | K36: ANTIOQUIA | L36: FAVORABLE | M36: 21/03/2025 | N36: SIN FALLO | P36: SI | T36: SI | V36: SI | X36: NO APLICA | AP36: MANUEL | AQ36: OK
A37: SOLUCIONES JURIDICAS Y EMPRESARIAL SJC SAS | B37: ID_007593070 | C37: 2024_5728767 | D37: 2528146 | E37: 05001310501520240000500 | G37: ORDINARIO LABORAL DE PRIMERA INSTANCIA | H37: 70552842 | I37: CARLOS ENRIQUE OROZCO ALVAREZ | J37: Colpensiones | K37: ANTIOQUIA | L37: FAVORABLE | M37: 23/01/2025 | N37: SIN FALLO | P37: SI | T37: SI | V37: SI | X37: NO APLICA | AP37: MANUEL | AQ37: OK
A38: WISS CONSULTORIA JURIDICA SAS | B38: ID_00456363 | C38: 2018_8387485 | D38: 1268180 | E38: 05001410500120170109400 | G38: ORDINARIO LABORAL DE UNICA INSTANCIA | H38: 70075902 | I38: HUMBERTO DE JESUS PASOS RESTREPO | J38: Colpensiones | K38: ANTIOQUIA | L38: FAVORABLE | M38: 15/03/2021 | N38: SIN FALLO | P38: SI | R38: SI | AP38: MANUEL | AQ38: OK
A39: UNION TEMPORAL SUPRA LEGAL | B39: ID_007747422 | C39: 2024_23927427 | D39: 2601282 | E39: 05001410500720241041400 | G39: EJECUTIVO LABORAL | H39: 43093205 | I39: MARIA DEL CARMEN OCHOA DUARTE | J39: Colpensiones | K39: ANTIOQUIA | L39: SIN FALLO | N39: SIN FALLO | Z39: SI | AB39: SI | AD39: SI | AF39: SI | AP39: MANUEL | AQ39: OK
A40: UNION TEMPORAL SUPRA LEGAL | B40: ID_007605080 | C40: 2024_7189386 | D40: 2532094 | E40: 05001310502420230037400 | G40: ORDINARIO LABORAL DE PRIMERA INSTANCIA | H40: 43528147 | I40: MADELEN MARIN FERNANDEZ | J40: Colpensiones | K40: ANTIOQUIA | L40: SIN FALLO | N40: SIN FALLO | P40: SI | T40: SI | V40: NO APLICA | X40: NO APLICA | AP40: MANUEL | AQ40: OK
...

Sheet Hoja1
A1: FIRMA | B1: ID_PROCESOS | C1: NO_BIZAGI | D1: ID_EKOGUI | E1: DIGITOS_23 | F1: 21 DIG | G1: TIPO_PROCESO | H1: IDENTIFICACION_DEMANDANTE | I1: NOMBRE_DEMANDANTE | J1: DEMANDADO | K1: REGIONAL | L1: SENTIDO_FALLO_1INSTANCIA | M1: FECHA_FALLO_1INSTANCIA | N1: SENTIDO_FALLO_2INSTANCIA | O1: FECHA_FALLO_2INSTANCIA | P1: DEMANDA | Q1: OBSERVACIÓN DEMANDA | R1: ACTA_DE_AUDIENCIA | S1: OBSERVACIÓN ACTA_DE_AUDIENCIA | T1: CONTESTACION_DE_DEMANDA | U1: OBSERVACIÓN CONTESTACION_DE_DEMANDA | V1: SENTENCIA_PRIMERA_INSTANCIA | W1: OBSERVACIÓN SENTENCIA_PRIMERA_INSTANCIA | X1: SENTENCIA_SEGUNDA_INSTANCIA | Y1: OBSERVACIÓN SENTENCIA_SEGUNDA_INSTANCIA | Z1: DEMANDA | AA1: OBSERVACIÓN DEMANDA | AB1: MANDAMIENTO_DE_PAGO | AC1: OBSERVACIÓN MANDAMIENTO_DE_PAGO | AD1: EXCEPCIONES_CONTESTACION | AE1: OBSERVACIÓN EXCEPCIONES_CONTESTACION | AF1: AUTO_QUE_ORDENA_CONTINUAR/NO_CONTINUAR_CON _LA_EJECUCION | AG1: OBSERVACIÓN AUTO_QUE_ORDENA_CONTINUAR/NO_CONTINUAR_CON _LA_EJECUCION | AH1: VALIDACIÓN | AI1: OBSERVACIÓN ERROR | AJ1: PROCEDE / NO PROCEDE ERROR | AK1: RAZÓN POR LA CUAL NO PROCEDE | AL1: OBSERVACIÓN REGIONAL | AM1: CONCLUSIÓN | AN1: ENCARGADO | AO1: ACTUALIZACION
A2: WISS CONSULTORIA JURIDICA SAS | B2: ID_00013353 | C2: 2013_2029083 | D2: 543906 | E2: 05001310500920130011400 | F2: 050013105009201300114 | G2: EJECUTIVO LABORAL | H2: 3390088 | I2: GABRIEL ENRIQUE HERNANDEZ LOPEZ | J2: COLPENSIONES | K2: ANTIOQUIA | L2: CONTINUA CON LA EJECUCION | M2: 21/10/2014 | N2: SIN FALLO | Z2: SI | AB2: SI | AD2: SI | AF2: SI | AN2: Leonardo | AO2: ID_00013353
A3: UNION TEMPORAL VILLEGAS CONSULTORES JURIDICOS | B3: ID_00017562 | C3: 2013_2880644 | D3: 1165031 | E3: 05001310502120120127300 | F3: 050013105021201201273 | G3: EJECUTIVO LABORAL | H3: 43062151 | I3: LUZ MARLENY TAMAYO | J3: COLPENSIONES | K3: ANTIOQUIA | L3: CONTINUA CON LA EJECUCION | M3: 1/08/2013 | N3: SIN FALLO | Z3: SI | AB3: SI | AD3: NO | AE3: No se cargó en la plataforma ekogui la pieza procesal MANDAMIENTO DE PAGO. | AF3: SI | AH3: ERROR | AN3: Leonardo | AO3: ID_00017562
A4: UNION TEMPORAL VILLEGAS CONSULTORES JURIDICOS | B4: ID_00024544 | C4: ISS_08456 | D4: 53654 | E4: 05001310500820090049900 | F4: 050013105008200900499 | G4: EJECUTIVO LABORAL | H4: 573575 | I4: CARLOS ENRIQUE GUTIERREZ QUINTERO | J4: ISS | K4: ANTIOQUIA | L4: CONTINUA CON LA EJECUCION | M4: 27/09/2010 | N4: SIN FALLO | Z4: SI | AB4: SI | AD4: SI | AF4: SI | AN4: Mary | AO4: ID_00024544
A5: UNION TEMPORAL VILLEGAS CONSULTORES JURIDICOS | B5: ID_00024560 | C5: ISS_04280 | D5: 53808 | E5: 05001310500820090087700 | F5: 050013105008200900877 | G5: EJECUTIVO LABORAL | H5: 590850 | I5: LUIS HORACIO CASTRO ALZATE | J5: ISS | K5: ANTIOQUIA | L5: CONTINUA CON LA EJECUCION | M5: 22/03/2011 | N5: CONTINUA CON LA EJECUCION | O5: 28/09/2012 | Z5: NO | AA5: No se cargó en la plataforma ekogui la pieza procesal DEMANDA QUE DA ORIGEN AL MANDAMIENTO DE PAGO. | AB5: SI | AD5: SI | AF5: SI | AH5: ERROR | AN5: Manuel | AO5: ID_00024560
A6: UNION TEMPORAL VILLEGAS CONSULTORES JURIDICOS | B6: ID_00024704 | C6: ISS_14399 | D6: 242307 | E6: 05001310500820100064500 | F6: 050013105008201000645 | G6: EJECUTIVO LABORAL | H6: 763300 | I6: PABLO EMILIO PANIAGUA GUTIERREZ | J6: ISS | K6: ANTIOQUIA | L6: CONTINUA CON LA EJECUCION | M6: 16/11/2011 | N6: SIN FALLO | Z6: SI | AB6: SI | AD6: SI | AF6: SI | AN6: Addy | AO6: ID_00024704
A7: UNION TEMPORAL VILLEGAS CONSULTORES JURIDICOS | B7: ID_00025089 | C7: ISS_11384 | D7: 1191645 | E7: 05001310500820110042900 | F7: 050013105008201100429 | G7: EJECUTIVO LABORAL | H7: 2463077 | I7: BERNARDO MEDINA MORALES | J7: ISS | K7: ANTIOQUIA | L7: CONTINUA CON LA EJECUCION | M7: 5/11/2014 | N7: SIN FALLO | Z7: NO | AA7: No se cargó en la plataforma ekogui la pieza procesal DEMANDA QUE DA ORIGEN AL MANDAMIENTO DE PAGO. | AB7: SI | AD7: SI | AF7: SI | AH7: ERROR | AN7: Leonardo | AO7: ID_00025089
A8: UNION TEMPORAL VILLEGAS CONSULTORES JURIDICOS | B8: ID_00025230 | C8: ISS_15003 | D8: 1178818 | E8: 05001310500520120020300 | F8: 050013105005201200203 | G8: ORDINARIO LABORAL DE PRIMERA INSTANCIA | H8: 2706192 | I8: MANUEL SALVADOR PIEDRAHITA | J8: ISS | K8: ANTIOQUIA | L8: FAVORABLE | M8: 25/05/2012 | N8: FAVORABLE | O8: 13/07/2012 | P8: SI | T8: NO | U8: No se cargó en la plataforma ekogui la pieza procesal CONTESTACION DE LA DEMANDA. | V8: SI | X8: SI | AH8: ERROR | AN8: Mary | AO8: ID_00025230
A9: UNION TEMPORAL VILLEGAS CONSULTORES JURIDICOS | B9: ID_00025353 | C9: ISS_19859 | D9: 242332 | E9: 05001310500820100081300 | F9: 050013105008201000813 | G9: EJECUTIVO LABORAL | H9: 3304942 | I9: IVAN DE JESUS VASQUEZ LARA | J9: ISS | K9: ANTIOQUIA | L9: CONTINUA CON LA EJECUCION | M9: 28/11/2011 | N9: SIN FALLO | Z9: NO | AA9: No se cargó en la plataforma ekogui la pieza procesal DEMANDA QUE DA ORIGEN AL MANDAMIENTO DE PAGO. | AB9: NO | AC9: No se cargó en la plataforma ekogui la pieza procesal MANDAMIENTO DE PAGO. | AD9: SI | AF9: SI | AH9: ERROR | AN9: Manuel | AO9: ID_00025353
A10: UNION TEMPORAL VILLEGAS CONSULTORES JURIDICOS | B10: ID_00025396 | C10: ISS_01925 | D10: 1378748 | E10: 05001310500820080060700 | F10: 050013105008200800607 | G10: EJECUTIVO LABORAL | H10: 3320375 | I10: RAMIRO DE JESUS AVENDAÑO ZAPATA | J10: ISS | K10: ANTIOQUIA | L10: CONTINUA CON LA EJECUCION | M10: 31/07/2012 | N10: SIN FALLO | Z10: SI | AB10: SI | AD10: SI | AF10: NO APLICA | AN10: Addy | AO10: ID_00025396
A11: UNION TEMPORAL VILLEGAS CONSULTORES JURIDICOS | B11: ID_00025402 | C11: ISS_14657 | D11: 162893 | E11: 05001310500820100098200 | F11: 050013105008201000982 | G11: EJECUTIVO LABORAL | H11: 3322265 | I11: JORGE PELAEZ VARGAS | J11: ISS | K11: ANTIOQUIA | L11: CONTINUA CON LA EJECUCION | M11: 13/09/2011 | N11: SIN FALLO | Z11: NO | AA11: No se cargó en la plataforma ekogui la pieza procesal DEMANDA QUE DA ORIGEN AL MANDAMIENTO DE PAGO. | AB11: SI | AD11: NO | AE11: No se cargó en la plataforma ekogui la pieza procesal MANDAMIENTO DE PAGO. | AF11: SI | AH11: ERROR | AN11: Leonardo | AO11: ID_00025402
